<?xml version="1.0"?>
<robot name="fs" xmlns:xacro="http://ros.org/wiki/xacro">

    <xacro:property name="M_PI" value="3.1415926535897931" />

    <material name="blue">
	    <color rgba="0 0 0.8 1"/>
    </material>

    <material name="white">
	    <color rgba="1 1 1 1"/>
    </material>

    <material name="black">
	    <color rgba="0 0 0 1"/>
    </material>

    <material name="green">
        <color rgba="0.0 0.8 0.0 1.0"/>
    </material>

    <link name="base_link">
        <!--<visual>
          <geometry>
             <box size="0.24 0.24 0.001"/>
          </geometry>
          <material name="white"/>
          <origin rpy="0 0 0" xyz="0 0 0.0005"/>
          <material>
            <color rgba="0 0 0.8 1" />
          </material>
        </visual> -->
        <collision>
          <origin rpy="0 0 0" xyz="0 0 0.0005"/>
          <geometry>
            <box size="0.22 0.22 0.001"/>
          </geometry>
        </collision>
    </link>

    <joint name="base_link_joint" type="fixed">
        <origin xyz="0 0 0.026" rpy="0 0 -1.5708" />
        <parent link="base_link" />
        <child link="base_plate" />
    </joint>

    <link name="base_plate">
    <visual>
      <origin rpy="0 0 0" xyz="0.03 0 -0.026"/>
      <geometry>
        <mesh filename="package://fs_hardware_interface/stl/Chasis.stl" scale="0.001 0.001 0.001"/>
      </geometry>
      <material name="white"/>
    </visual>
    <collision>
      <origin rpy="0 0 0" xyz="0.03 0 -0.026"  />
      <geometry>
        <mesh filename="package://fs_hardware_interface/stl/Chasis.stl" scale="0.001 0.001 0.001" />
      </geometry>
    </collision>
    </link>   
    
    
    <joint name="JointBaseWheelBL" type="continuous">
        <origin xyz="-0.08 -0.06 0.015" rpy="0 0 0" />
        <parent link="base_plate" />
        <child link="left_wheel" />
        <axis xyz="-1 0 0" />
    </joint>

    <link name="left_wheel">
    <visual>
      <origin rpy="0 0 0" xyz="0.11 0.059 -0.04"/>
      <geometry>
        <mesh filename="package://fs_hardware_interface/stl/Wheel.stl" scale="0.001 0.001 0.001"/>
      </geometry>
      <material name="black"/>
    </visual>
    <collision>
      <origin rpy="0 0 0" xyz="0.11 0.059 -0.04"/>
      <geometry>
        <mesh filename="package://fs_hardware_interface/stl/Wheel.stl" scale="0.001 0.001 0.001" />
      </geometry>
    </collision>
    </link>   
    
    <joint name="JointBaseWheelBR" type="continuous">
        <origin xyz="0.08 -0.06 0.015" rpy="0 0 0" />
        <parent link="base_plate" />
        <child link="right_wheel" />
        <axis xyz="-1 0 0" />
    </joint>

    <link name="right_wheel">
    <visual>
      <origin rpy="0 0 0" xyz="0.133 0.059 -0.04"/>
      <geometry>
        <mesh filename="package://fs_hardware_interface/stl/Wheel.stl" scale="0.001 0.001 0.001"/>
      </geometry>
      <material name="black"/>
    </visual>
    <collision>
      <origin rpy="0 0 0" xyz="0.133 0.059 -0.04"/>
      <geometry>
        <mesh filename="package://fs_hardware_interface/stl/Wheel.stl" scale="0.001 0.001 0.001" />
      </geometry>
    </collision>
    </link>

    <joint name="JointSteerRight" type="revolute">
        <axis xyz="0 0 1"/>
        <parent link="base_plate"/>
        <child link="steer_right_shaft"/>
        <origin  xyz="0.08 0.15 0.015" rpy="0 0 0" />
        <limit effort="173" lower="${-45*M_PI/180}" upper="${45*M_PI/180}" velocity="${M_PI*2*10}"/>
    </joint>

    <link name="steer_right_shaft">
        <visual>
            <origin rpy="0 0 0" xyz="0 0 0"/>
            <geometry>
                <cylinder length="0.02" radius="0.002"/>
            </geometry>
            <material name="green"/>
        </visual>
        <collision>
            <origin rpy="0 0 0" xyz="0 0 0"/>
            <geometry>
                <cylinder length="0.02" radius="0.002"/>
            </geometry>
        </collision>
    </link>


    <joint name="JointBaseWheelFR" type="continuous">
        <origin xyz="0 0 0" rpy="0 0 0" />
        <parent link="steer_right_shaft" />
        <child link="front_right_wheel" />
        <axis xyz="-1 0 0" />
    </joint>

    <link name="front_right_wheel">
        <visual>
            <origin rpy="0 0 0" xyz="0.133 0.059 -0.04"/>
            <geometry>
                <mesh filename="package://fs_hardware_interface/stl/Wheel.stl" scale="0.001 0.001 0.001"/>
            </geometry>
            <material name="black"/>
        </visual>
        <collision>
            <origin rpy="0 0 0" xyz="0.133 0.059 -0.04"/>
            <geometry>
                <mesh filename="package://fs_hardware_interface/stl/Wheel.stl" scale="0.001 0.001 0.001" />
            </geometry>
        </collision>
    </link>



    <joint name="JointSteerLeft" type="revolute">
        <axis xyz="0 0 1"/>
        <parent link="base_plate"/>
        <child link="steer_left_shaft"/>
        <origin  xyz="-0.08 0.15 0.015" rpy="0 0 0" />
        <limit effort="173" lower="${-45*M_PI/180}" upper="${45*M_PI/180}" velocity="${M_PI*2*10}"/>
    </joint>

    <link name="steer_left_shaft">
        <visual>
            <origin rpy="0 0 0" xyz="0 0 0"/>
            <geometry>
                <cylinder length="0.02" radius="0.002"/>
            </geometry>
            <material name="green"/>
        </visual>
        <collision>
            <origin rpy="0 0 0" xyz="0 0 0"/>
            <geometry>
                <cylinder length="0.02" radius="0.002"/>
            </geometry>
        </collision>
    </link>

    <!-- -->

    <joint name="JointBaseWheelFL" type="continuous">
        <origin xyz="0 0 0" rpy="0 0 0" />
        <parent link="steer_left_shaft" />
        <child link="front_left_wheel" />
        <axis xyz="-1 0 0" />
    </joint>


    <link name="front_left_wheel">
        <visual>
            <origin rpy="0 0 0" xyz="0.11 0.059 -0.04"/>
            <geometry>
                <mesh filename="package://fs_hardware_interface/stl/Wheel.stl" scale="0.001 0.001 0.001"/>
            </geometry>
            <material name="black"/>
        </visual>
        <collision>
            <origin rpy="0 0 0" xyz="0.11 0.059 -0.04"/>
            <geometry>
                <mesh filename="package://fs_hardware_interface/stl/Wheel.stl" scale="0.001 0.001 0.001" />
            </geometry>
        </collision>
    </link>

 <!--

    <joint name="JointSteer" type="continuous">
        <origin xyz="0 0.12 0.015" rpy="0 0 0" />
        <parent link="base_plate" />
        <child link="steer_shaft" />
        <axis xyz="0 0 1" />
    </joint>

    <link name="steer_shaft">
        <visual>
            <origin rpy="0 0 0" xyz="0 0 0"/>
            <geometry>
                <cylinder length="0.02" radius="0.002"/>
            </geometry>
            <material name="green"/>
        </visual>
        <collision>
            <origin rpy="0 0 0" xyz="0 0 0"/>
            <geometry>
                <cylinder length="0.02" radius="0.002"/>
            </geometry>
        </collision>
    </link>


    <joint name="shaft_joint" type="fixed">
        <origin rpy="0 0 0" xyz="0.0 0 0.01"/>
        <parent link="steer_shaft"/>
        <child link="shaft_bar"/>
    </joint>

    <link name="shaft_bar">
        <visual>
            <geometry>
                <box size="0.05 0.02 0.001"/>
            </geometry>
            <material name="blue"/>
            <origin rpy="0 0 0" xyz="0.015 0 0"/>
        </visual>
    </link>

-->













    <joint name="laser_joint" type="fixed">
        <origin xyz="0 0.040 0.090" rpy="0 0 1.5708" />
        <parent link="base_plate" />
        <child link="laser" />
    </joint>

    <link name="laser">
    <visual>
      <origin rpy="0 0 -1.5708" xyz="0.084 -0.242 -0.098"/>
      <geometry>
        <mesh filename="package://fs_hardware_interface/stl/RpLidar.stl" scale="0.001 0.001 0.001"/>
      </geometry>
      <material name="blue"/>
    </visual>
    <collision>
      <origin rpy="0 0 0" xyz="0.242 0.084 -0.098"  />
      <geometry>
        <mesh filename="package://fs_hardware_interface/stl/RpLidar.stl" scale="0.001 0.001 0.001" />
      </geometry>
    </collision>
    </link>

</robot>
