<?xml version="1.0"?>
<robot name="fs" xmlns:xacro="http://ros.org/wiki/xacro">

    <xacro:property name="M_PI" value="3.1415926535897931" />

    <material name="blue">
	    <color rgba="0 0 0.8 1"/>
    </material>

    <material name="white">
	    <color rgba="1 1 1 1"/>
    </material>

    <material name="black">
	    <color rgba="0 0 0 1"/>
    </material>

    <material name="green">
        <color rgba="0.0 0.8 0.0 1.0"/>
    </material>

    <link name="base_link">
        <!--<visual>
          <geometry>
             <box size="0.24 0.24 0.001"/>
          </geometry>
          <material name="white"/>
          <origin rpy="0 0 0" xyz="0 0 0.0005"/>
          <material>
            <color rgba="0 0 0.8 1" />
          </material>
        </visual> -->
        <collision>
            <origin rpy="0 0 0" xyz="0.003 0.16 0.05"/>
            <geometry>
                <box size="0.2 0.34 0.1"/>
            </geometry>
        </collision>
    </link>

    <joint name="base_link_joint" type="fixed">
        <origin xyz="-0.100 0 0.026" rpy="0 0 -1.5708" />
        <parent link="base_link" />
        <child link="base_plate" />
    </joint>

    <link name="base_plate">
    <visual>
      <origin rpy="0 0 0" xyz="0.003 0.108 -0.045"/>
      <geometry>
        <mesh filename="package://fs_hardware_interface/new_stl/FS_Chassis_mm.stl" scale="0.001 0.001 0.001"/>
      </geometry>
      <material name="white"/>
    </visual>
    <collision>
      <origin rpy="0 0 0" xyz="0.003 0.108 -0.045"  />
      <geometry>
        <mesh filename="package://fs_hardware_interface/new_stl/FS_Chassis_mm.stl" scale="0.001 0.001 0.001" />
      </geometry>
    </collision>
    </link>   
    
    
    <joint name="JointBaseWheelBL" type="continuous">
        <origin xyz="-0.105 0.040 0.01481" rpy="0 0 0" />
        <parent link="base_plate" />
        <child link="left_wheel" />
        <axis xyz="-1 0 0" />
    </joint>

    <link name="left_wheel">
    <visual>
      <origin rpy="0 0 0" xyz="0.11 0.059 -0.04"/>
      <geometry>
        <mesh filename="package://fs_hardware_interface/stl/Wheel.stl" scale="0.001 0.001 0.001"/>
      </geometry>
      <material name="black"/>
    </visual>
    <collision>
      <origin rpy="0 0 0" xyz="0.11 0.059 -0.04"/>
      <geometry>
        <mesh filename="package://fs_hardware_interface/stl/Wheel.stl" scale="0.001 0.001 0.001" />
      </geometry>
    </collision>
    </link>   
    
    <joint name="JointBaseWheelBR" type="continuous">
        <origin xyz="0.105 0.040 0.01481" rpy="0 0 0" />
        <parent link="base_plate" />
        <child link="right_wheel" />
        <axis xyz="-1 0 0" />
    </joint>

    <link name="right_wheel">
    <visual>
      <origin rpy="0 0 0" xyz="0.133 0.059 -0.04"/>
      <geometry>
        <mesh filename="package://fs_hardware_interface/stl/Wheel.stl" scale="0.001 0.001 0.001"/>
      </geometry>
      <material name="black"/>
    </visual>
    <collision>
      <origin rpy="0 0 0" xyz="0.133 0.059 -0.04"/>
      <geometry>
        <mesh filename="package://fs_hardware_interface/stl/Wheel.stl" scale="0.001 0.001 0.001" />
      </geometry>
    </collision>
    </link>

    <joint name="JointSteerRight" type="revolute">
        <axis xyz="0 0 1"/>
        <parent link="base_plate"/>
        <child link="steer_right_shaft"/>
        <origin  xyz="0.0825 0.210 0.020" rpy="0 0 0" />
        <limit effort="173" lower="${-45*M_PI/180}" upper="${45*M_PI/180}" velocity="${M_PI*2*10}"/>
    </joint>

    <link name="steer_right_shaft">
        <visual>
            <origin rpy="0 0 0" xyz="0 0 0"/>
            <geometry>
                <cylinder length="0.02" radius="0.002"/>
            </geometry>
            <material name="green"/>
        </visual>
        <collision>
            <origin rpy="0 0 0" xyz="0 0 0"/>
            <geometry>
                <cylinder length="0.02" radius="0.002"/>
            </geometry>
        </collision>
    </link>


    <joint name="JointBaseWheelFR" type="continuous">
        <origin xyz="0.022 0 -0.006" rpy="0 0 0" />
        <parent link="steer_right_shaft" />
        <child link="front_right_wheel" />
        <axis xyz="-1 0 0" />
    </joint>

    <link name="front_right_wheel">
        <visual>
            <origin rpy="0 0 0" xyz="0.133 0.059 -0.04"/>
            <geometry>
                <mesh filename="package://fs_hardware_interface/stl/Wheel.stl" scale="0.001 0.001 0.001"/>
            </geometry>
            <material name="black"/>
        </visual>
        <collision>
            <origin rpy="0 0 0" xyz="0.133 0.059 -0.04"/>
            <geometry>
                <mesh filename="package://fs_hardware_interface/stl/Wheel.stl" scale="0.001 0.001 0.001" />
            </geometry>
        </collision>
    </link>



    <joint name="JointSteerLeft" type="revolute">
        <axis xyz="0 0 1"/>
        <parent link="base_plate"/>
        <child link="steer_left_shaft"/>
        <origin  xyz="-0.0825 0.210 0.020" rpy="0 0 0" />
        <limit effort="173" lower="${-45*M_PI/180}" upper="${45*M_PI/180}" velocity="${M_PI*2*10}"/>
    </joint>

    <link name="steer_left_shaft">
        <visual>
            <origin rpy="0 0 0" xyz="0 0 0"/>
            <geometry>
                <cylinder length="0.02" radius="0.002"/>
            </geometry>
            <material name="green"/>
        </visual>
        <collision>
            <origin rpy="0 0 0" xyz="0 0 0"/>
            <geometry>
                <cylinder length="0.02" radius="0.002"/>
            </geometry>
        </collision>
    </link>

    <!-- -->

    <joint name="JointBaseWheelFL" type="continuous">
        <origin xyz="-0.022 0 -0.006" rpy="0 0 0" />
        <parent link="steer_left_shaft" />
        <child link="front_left_wheel" />
        <axis xyz="-1 0 0" />
    </joint>


    <link name="front_left_wheel">
        <visual>
            <origin rpy="0 0 0" xyz="0.11 0.059 -0.04"/>
            <geometry>
                <mesh filename="package://fs_hardware_interface/stl/Wheel.stl" scale="0.001 0.001 0.001"/>
            </geometry>
            <material name="black"/>
        </visual>
        <collision>
            <origin rpy="0 1.57 0" xyz="0.11 0 0"/>
            <geometry>
                <cylinder length="0.02" radius="0.045"/>
            </geometry>
        </collision>
    </link>

 <!--

    <joint name="JointSteer" type="continuous">
        <origin xyz="0 0.12 0.015" rpy="0 0 0" />
        <parent link="base_plate" />
        <child link="steer_shaft" />
        <axis xyz="0 0 1" />
    </joint>

    <link name="steer_shaft">
        <visual>
            <origin rpy="0 0 0" xyz="0 0 0"/>
            <geometry>
                <cylinder length="0.02" radius="0.002"/>
            </geometry>
            <material name="green"/>
        </visual>
        <collision>
            <origin rpy="0 0 0" xyz="0 0 0"/>
            <geometry>
                <cylinder length="0.02" radius="0.002"/>
            </geometry>
        </collision>
    </link>


    <joint name="shaft_joint" type="fixed">
        <origin rpy="0 0 0" xyz="0.0 0 0.01"/>
        <parent link="steer_shaft"/>
        <child link="shaft_bar"/>
    </joint>

    <link name="shaft_bar">
        <visual>
            <geometry>
                <box size="0.05 0.02 0.001"/>
            </geometry>
            <material name="blue"/>
            <origin rpy="0 0 0" xyz="0.015 0 0"/>
        </visual>
    </link>

-->



    <joint name="laser_joint" type="fixed">
        <origin xyz="0 0.300 0.045" rpy="0 0 1.5708" />
        <parent link="base_plate" />
        <child link="laser" />
    </joint>

    <link name="laser">
    <visual>
      <origin rpy="0 0 -1.5708" xyz="0.084 -0.242 -0.098"/>
      <geometry>
        <mesh filename="package://fs_hardware_interface/stl/RpLidar.stl" scale="0.001 0.001 0.001"/>
      </geometry>
      <material name="blue"/>
    </visual>
    <collision>
      <origin rpy="0 0 0" xyz="0.242 0.084 -0.098"  />
      <geometry>
        <mesh filename="package://fs_hardware_interface/stl/RpLidar.stl" scale="0.001 0.001 0.001" />
      </geometry>
    </collision>
    </link>


    <joint name="camera_joint" type="fixed">
        <origin xyz="0 0.2745 0.125" rpy="0 ${(M_PI*25/180)} ${M_PI/2}" />
        <parent link="base_plate" />
        <child link="camera" />
    </joint>

    <link name="camera">
        <visual>
            <origin rpy="0 0 0" xyz="0 0 0"/>
            <geometry>
                <mesh filename="package://fs_hardware_interface/new_stl/camera_lens.stl" scale="0.001 0.001 0.001"/>
            </geometry>
            <material name="blue"/>
        </visual>
    </link>

    <joint name="camera3d_joint" type="fixed">
        <origin xyz="0 0.2745 0.125" rpy="${-(25*M_PI/180) - M_PI/2} 0 0" />
        <parent link="base_plate"/>
        <child link="camera3d_link"/>
      </joint>
      
      <link name="camera3d_link">
        <inertial>
          <mass value="1e-5" />
          <origin xyz="0 0 0" rpy="0 0 0"/>
          <inertia ixx="1e-6" ixy="0" ixz="0" iyy="1e-6" iyz="0" izz="1e-6" />
        </inertial>
      </link>



</robot>
